Workbook

Sheet PDF_Stats
A1: Statement ID | B1: PDF Link | C1: Type | D1: Countries | E1: Trademarks | F1: AnnualRevenue | G1: Entities | H1: IndustrySectors | I1: OverseasObligations | J1: Number Of Pages | K1: Scan Rate | L1: Words per Page (Median) | M1: Status | N1: Number Of Pages | O1: Scan Rate | P1: Words per Page (Median) | Q1: Status
A2: 12 | B2: https://modernslaveryregister.gov.au/statements/12/ | C2: =VLOOKUP($A2,Sheet1!$A$2:$I$6793,2,FALSE) -> Joint | D2: =VLOOKUP($A2,Sheet1!$A$2:$I$6793,3,FALSE) -> Australia | E2: QinetiQ Pty Ltd | F2: 100-150M | G2: Qinetiq Pty Ltd (68 125 805 647) | J2: 7 | K2: 0.28571429 | L2: 514 | M2: =IF($K2 < 0.15, "Not Scanned",IF($K2 < 0.55, "Partially Scanned",IF($K2 >= 0.55, "Fully Scanned","Not Found"))) -> Partially Scanned | N2: 7 | O2: 0.28571429 | P2: 514 | Q2: =IF($K2 < 0.15, "Not Scanned",IF($K2 < 0.55, "Partially Scanned",IF($K2 >= 0.55, "Fully Scanned","Not Found"))) -> Partially Scanned
A3: 16 | B3: https://modernslaveryregister.gov.au/statements/16/ | C3: =VLOOKUP($A3,Sheet1!$A$2:$I$6793,2,FALSE) -> Normal | D3: =VLOOKUP($A3,Sheet1!$A$2:$I$6793,3,FALSE) -> Australia | F3: Unknown | G3: ORIX AUSTRALIA CORPORATION LIMITED (79 002 992 681) | J3: 11 | K3: 0.18181818 | L3: 147 | M3: =IF($K3 < 0.15, "Not Scanned",IF($K3 < 0.55, "Partially Scanned",IF($K3 >= 0.55, "Fully Scanned","Not Found"))) -> Partially Scanned | N3: 11 | O3: 0.18181818 | P3: 147 | Q3: =IF($K3 < 0.15, "Not Scanned",IF($K3 < 0.55, "Partially Scanned",IF($K3 >= 0.55, "Fully Scanned","Not Found"))) -> Partially Scanned
A4: 20 | B4: https://modernslaveryregister.gov.au/statements/20/ | C4: =VLOOKUP($A4,Sheet1!$A$2:$I$6793,2,FALSE) -> Normal | D4: =VLOOKUP($A4,Sheet1!$A$2:$I$6793,3,FALSE) -> Australia | F4: 500-600M | G4: THE UNIVERSITY OF NEWCASTLE (15 736 576 735) | J4: 16 | K4: 1 | L4: 0 | M4: =IF($K4 < 0.15, "Not Scanned",IF($K4 < 0.55, "Partially Scanned",IF($K4 >= 0.55, "Fully Scanned","Not Found"))) -> Fully Scanned | N4: 16 | O4: 1 | P4: 0 | Q4: =IF($K4 < 0.15, "Not Scanned",IF($K4 < 0.55, "Partially Scanned",IF($K4 >= 0.55, "Fully Scanned","Not Found"))) -> Fully Scanned
A5: 24 | B5: https://modernslaveryregister.gov.au/statements/24/ | C5: =VLOOKUP($A5,Sheet1!$A$2:$I$6793,2,FALSE) -> Joint | D5: =VLOOKUP($A5,Sheet1!$A$2:$I$6793,3,FALSE) -> United States of America | F5: Unknown | G5: Reinsurance Group of America Incorporated, RGA REINSURANCE COMPANY OF AUSTRALIA LIMITED (14 072 292 712), RGA UK Services Limited | J5: 3 | K5: 1 | L5: 0 | M5: =IF($K5 < 0.15, "Not Scanned",IF($K5 < 0.55, "Partially Scanned",IF($K5 >= 0.55, "Fully Scanned","Not Found"))) -> Fully Scanned | N5: 3 | O5: 1 | P5: 0 | Q5: =IF($K5 < 0.15, "Not Scanned",IF($K5 < 0.55, "Partially Scanned",IF($K5 >= 0.55, "Fully Scanned","Not Found"))) -> Fully Scanned
A6: 35 | B6: https://modernslaveryregister.gov.au/statements/35/ | C6: =VLOOKUP($A6,Sheet1!$A$2:$I$6793,2,FALSE) -> Normal | D6: =VLOOKUP($A6,Sheet1!$A$2:$I$6793,3,FALSE) -> Australia | F6: Unknown | G6: ALDI STORES (A LIMITED PARTNERSHIP) (90 196 565 019) | J6: 23 | K6: 0.043478261 | L6: 244 | M6: =IF($K6 < 0.15, "Not Scanned",IF($K6 < 0.55, "Partially Scanned",IF($K6 >= 0.55, "Fully Scanned","Not Found"))) -> Not Scanned | N6: 23 | O6: 0.043478261 | P6: 244 | Q6: =IF($K6 < 0.15, "Not Scanned",IF($K6 < 0.55, "Partially Scanned",IF($K6 >= 0.55, "Fully Scanned","Not Found"))) -> Not Scanned
A7: 37 | B7: https://modernslaveryregister.gov.au/statements/37/ | C7: =VLOOKUP($A7,Sheet1!$A$2:$I$6793,2,FALSE) -> Joint | D7: =VLOOKUP($A7,Sheet1!$A$2:$I$6793,3,FALSE) -> Australia | E7: KPMG Australia | F7: Unknown | G7: KPMG Australia (51 194 660 183), KPMG FINANCIAL ADVISORY SERVICES (AUSTRALIA) PTY LTD (43 007 363 215), KPMG HOLDINGS (AUSTRALIA) PTY LTD (34 064 067 241), The Trustee for KPMG AUSTRALIAN SERVICE TRUST (87 160 010 116) | J7: 22 | K7: 0.045454545 | L7: 397 | M7: =IF($K7 < 0.15, "Not Scanned",IF($K7 < 0.55, "Partially Scanned",IF($K7 >= 0.55, "Fully Scanned","Not Found"))) -> Not Scanned | N7: 22 | O7: 0.045454545 | P7: 397 | Q7: =IF($K7 < 0.15, "Not Scanned",IF($K7 < 0.55, "Partially Scanned",IF($K7 >= 0.55, "Fully Scanned","Not Found"))) -> Not Scanned
A8: 39 | B8: https://modernslaveryregister.gov.au/statements/39/ | C8: =VLOOKUP($A8,Sheet1!$A$2:$I$6793,2,FALSE) -> Joint | D8: =VLOOKUP($A8,Sheet1!$A$2:$I$6793,3,FALSE) -> Australia | E8: Santos | F8: 1BN+ | G8: SANTOS LIMITED (80 007 550 923) | J8: 22 | K8: 0.045454545 | L8: 269 | M8: =IF($K8 < 0.15, "Not Scanned",IF($K8 < 0.55, "Partially Scanned",IF($K8 >= 0.55, "Fully Scanned","Not Found"))) -> Not Scanned | N8: 22 | O8: 0.045454545 | P8: 269 | Q8: =IF($K8 < 0.15, "Not Scanned",IF($K8 < 0.55, "Partially Scanned",IF($K8 >= 0.55, "Fully Scanned","Not Found"))) -> Not Scanned
A9: 40 | B9: https://modernslaveryregister.gov.au/statements/40/ | C9: =VLOOKUP($A9,Sheet1!$A$2:$I$6793,2,FALSE) -> Normal | D9: =VLOOKUP($A9,Sheet1!$A$2:$I$6793,3,FALSE) -> Ireland | E9: Kerry | F9: 200-250M | G9: KERRY INGREDIENTS AUSTRALIA PTY. LIMITED (47 072 996 895) | J9: 3 | K9: 0 | L9: 765 | M9: =IF($K9 < 0.15, "Not Scanned",IF($K9 < 0.55, "Partially Scanned",IF($K9 >= 0.55, "Fully Scanned","Not Found"))) -> Not Scanned | N9: 3 | O9: 0 | P9: 765 | Q9: =IF($K9 < 0.15, "Not Scanned",IF($K9 < 0.55, "Partially Scanned",IF($K9 >= 0.55, "Fully Scanned","Not Found"))) -> Not Scanned
A10: 41 | B10: https://modernslaveryregister.gov.au/statements/41/ | C10: =VLOOKUP($A10,Sheet1!$A$2:$I$6793,2,FALSE) -> Joint | D10: =VLOOKUP($A10,Sheet1!$A$2:$I$6793,3,FALSE) -> United Kingdom | E10: BT | F10: 200-250M | G10: BT AUSTRALASIA PTY LIMITED (93 003 050 146) | J10: 22 | K10: 0.045454545 | L10: 377.5 | M10: =IF($K10 < 0.15, "Not Scanned",IF($K10 < 0.55, "Partially Scanned",IF($K10 >= 0.55, "Fully Scanned","Not Found"))) -> Not Scanned | N10: 22 | O10: 0.045454545 | P10: 377.5 | Q10: =IF($K10 < 0.15, "Not Scanned",IF($K10 < 0.55, "Partially Scanned",IF($K10 >= 0.55, "Fully Scanned","Not Found"))) -> Not Scanned
A11: 49 | B11: https://modernslaveryregister.gov.au/statements/49/ | C11: =VLOOKUP($A11,Sheet1!$A$2:$I$6793,2,FALSE) -> Normal | D11: =VLOOKUP($A11,Sheet1!$A$2:$I$6793,3,FALSE) -> Australia | E11: Bose, Bose Corporation | F11: Unknown | G11: Bose Pty Ltd | H11: Other | I11: United Kingdom Modern Slavery Act 2015 California Transparency in Supply Chains Act 2010 | J11: 3 | K11: 1 | L11: 0 | M11: =IF($K11 < 0.15, "Not Scanned",IF($K11 < 0.55, "Partially Scanned",IF($K11 >= 0.55, "Fully Scanned","Not Found"))) -> Fully Scanned | N11: 3 | O11: 1 | P11: 0 | Q11: =IF($K11 < 0.15, "Not Scanned",IF($K11 < 0.55, "Partially Scanned",IF($K11 >= 0.55, "Fully Scanned","Not Found"))) -> Fully Scanned
A12: 51 | B12: https://modernslaveryregister.gov.au/statements/51/ | C12: =VLOOKUP($A12,Sheet1!$A$2:$I$6793,2,FALSE) -> Joint | D12: =VLOOKUP($A12,Sheet1!$A$2:$I$6793,3,FALSE) -> Australia, New Zealand | E12: Xero, HubDoc, WorkflowMax | F12: 700-800M | G12: XERO AUSTRALIA PTY LIMITED (89 124 215 247), Xero Limited (81 160 661 183) | J12: 8 | K12: 0 | L12: 281.5 | M12: =IF($K12 < 0.15, "Not Scanned",IF($K12 < 0.55, "Partially Scanned",IF($K12 >= 0.55, "Fully Scanned","Not Found"))) -> Not Scanned | N12: 8 | O12: 0 | P12: 281.5 | Q12: =IF($K12 < 0.15, "Not Scanned",IF($K12 < 0.55, "Partially Scanned",IF($K12 >= 0.55, "Fully Scanned","Not Found"))) -> Not Scanned
A13: 58 | B13: https://modernslaveryregister.gov.au/statements/58/ | C13: =VLOOKUP($A13,Sheet1!$A$2:$I$6793,2,FALSE) -> Joint | D13: =VLOOKUP($A13,Sheet1!$A$2:$I$6793,3,FALSE) -> Australia, United Kingdom | E13: Menzies Aviation, AMI, Air Menzies International | F13: 300-350M | G13: John Menzies plc, MENZIES AVIATION (GROUND SERVICES) AUSTRALIA PTY LTD (63 085 693 269), MENZIES AVIATION HOLDINGS (AUSTRALIA) PTY LTD (18 102 031 836) | J13: 8 | K13: 0.625 | L13: 9.5 | M13: =IF($K13 < 0.15, "Not Scanned",IF($K13 < 0.55, "Partially Scanned",IF($K13 >= 0.55, "Fully Scanned","Not Found"))) -> Fully Scanned | N13: 8 | O13: 0.625 | P13: 9.5 | Q13: =IF($K13 < 0.15, "Not Scanned",IF($K13 < 0.55, "Partially Scanned",IF($K13 >= 0.55, "Fully Scanned","Not Found"))) -> Fully Scanned
A14: 61 | B14: https://modernslaveryregister.gov.au/statements/61/ | C14: =VLOOKUP($A14,Sheet1!$A$2:$I$6793,2,FALSE) -> Joint | D14: =VLOOKUP($A14,Sheet1!$A$2:$I$6793,3,FALSE) -> Australia | E14: Baby Bunting | F14: 800-900M | G14: BABY BUNTING GROUP LIMITED (58 128 533 693), BABY BUNTING PTY LTD (43 128 546 154) | H14: Durable consumer goods, including electronics and appliances, home furnishings and other accessories Fashion, textiles, apparel and luxury goods | J14: 3 | K14: 0 | L14: 583 | M14: =IF($K14 < 0.15, "Not Scanned",IF($K14 < 0.55, "Partially Scanned",IF($K14 >= 0.55, "Fully Scanned","Not Found"))) -> Not Scanned | N14: 3 | O14: 0 | P14: 583 | Q14: =IF($K14 < 0.15, "Not Scanned",IF($K14 < 0.55, "Partially Scanned",IF($K14 >= 0.55, "Fully Scanned","Not Found"))) -> Not Scanned
A15: 62 | B15: https://modernslaveryregister.gov.au/statements/62/ | C15: =VLOOKUP($A15,Sheet1!$A$2:$I$6793,2,FALSE) -> Normal | D15: =VLOOKUP($A15,Sheet1!$A$2:$I$6793,3,FALSE) -> Japan | F15: Unknown | G15: OBAYASHI CORPORATION (86 002 932 756) | H15: Construction, civil engineering and building products | I15: United Kingdom Modern Slavery Act 2015 | J15: 8 | K15: 0.125 | L15: 360.5 | M15: =IF($K15 < 0.15, "Not Scanned",IF($K15 < 0.55, "Partially Scanned",IF($K15 >= 0.55, "Fully Scanned","Not Found"))) -> Not Scanned | N15: 8 | O15: 0.125 | P15: 360.5 | Q15: =IF($K15 < 0.15, "Not Scanned",IF($K15 < 0.55, "Partially Scanned",IF($K15 >= 0.55, "Fully Scanned","Not Found"))) -> Not Scanned
A16: 68 | B16: https://modernslaveryregister.gov.au/statements/68/ | C16: =VLOOKUP($A16,Sheet1!$A$2:$I$6793,2,FALSE) -> Joint | D16: =VLOOKUP($A16,Sheet1!$A$2:$I$6793,3,FALSE) -> United States of America | E16: Jamf Holding Corp. | F16: 200-250M | G16: JAMF SOFTWARE AUSTRALIA PTY LTD (47 165 322 154) | J16: 2 | K16: 0 | L16: 346.5 | M16: =IF($K16 < 0.15, "Not Scanned",IF($K16 < 0.55, "Partially Scanned",IF($K16 >= 0.55, "Fully Scanned","Not Found"))) -> Not Scanned | N16: 2 | O16: 0 | P16: 346.5 | Q16: =IF($K16 < 0.15, "Not Scanned",IF($K16 < 0.55, "Partially Scanned",IF($K16 >= 0.55, "Fully Scanned","Not Found"))) -> Not Scanned
A17: 70 | B17: https://modernslaveryregister.gov.au/statements/70/ | C17: =VLOOKUP($A17,Sheet1!$A$2:$I$6793,2,FALSE) -> Joint | D17: =VLOOKUP($A17,Sheet1!$A$2:$I$6793,3,FALSE) -> United States of America | E17: Nielsen, Nielsen IQ, Nielsen Connect, Nielsen TAM, Netratings, Nielsen Sports | F17: 1BN+ | G17: NETRATINGS AUSTRALIA PTY LIMITED (47 081 796 287), NIELSEN CONNECT AUSTRALIA PTY LTD (97 638 234 474), NIELSEN SPORTS PTY LTD (59 106 863 325), NIELSEN TELEVISION AUDIENCE MEASUREMENT PTY LTD (57 089 686 500), THE NIELSEN COMPANY (AUSTRALIA) PTY LTD (35 008 417 874) | J17: 10 | K17: 0.1 | L17: 358.5 | M17: =IF($K17 < 0.15, "Not Scanned",IF($K17 < 0.55, "Partially Scanned",IF($K17 >= 0.55, "Fully Scanned","Not Found"))) -> Not Scanned | N17: 10 | O17: 0.1 | P17: 358.5 | Q17: =IF($K17 < 0.15, "Not Scanned",IF($K17 < 0.55, "Partially Scanned",IF($K17 >= 0.55, "Fully Scanned","Not Found"))) -> Not Scanned
A18: 74 | B18: https://modernslaveryregister.gov.au/statements/74/ | C18: =VLOOKUP($A18,Sheet1!$A$2:$I$6793,2,FALSE) -> Normal | D18: =VLOOKUP($A18,Sheet1!$A$2:$I$6793,3,FALSE) -> Australia | F18: 800-900M | G18: BRADKEN PTY LIMITED (33 108 693 009) | H18: Other | J18: 14 | K18: 0 | L18: 471.5 | M18: =IF($K18 < 0.15, "Not Scanned",IF($K18 < 0.55, "Partially Scanned",IF($K18 >= 0.55, "Fully Scanned","Not Found"))) -> Not Scanned | N18: 14 | O18: 0 | P18: 471.5 | Q18: =IF($K18 < 0.15, "Not Scanned",IF($K18 < 0.55, "Partially Scanned",IF($K18 >= 0.55, "Fully Scanned","Not Found"))) -> Not Scanned
A19: 75 | B19: https://modernslaveryregister.gov.au/statements/75/ | C19: =VLOOKUP($A19,Sheet1!$A$2:$I$6793,2,FALSE) -> Joint | D19: =VLOOKUP($A19,Sheet1!$A$2:$I$6793,3,FALSE) -> Australia, Singapore | E19: Australasian Solvents and Chemical Company, ASCC, Taytonn | F19: 250-300M | G19: AUSTRALASIAN SOLVENTS AND CHEMICALS COMPANY PTY. LTD. (57 095 441 080) | H19: Mining, metals, chemicals and resources (including oil and gas) | J19: 3 | K19: 1 | L19: 0 | M19: =IF($K19 < 0.15, "Not Scanned",IF($K19 < 0.55, "Partially Scanned",IF($K19 >= 0.55, "Fully Scanned","Not Found"))) -> Fully Scanned | N19: 3 | O19: 1 | P19: 0 | Q19: =IF($K19 < 0.15, "Not Scanned",IF($K19 < 0.55, "Partially Scanned",IF($K19 >= 0.55, "Fully Scanned","Not Found"))) -> Fully Scanned
A20: 77 | B20: https://modernslaveryregister.gov.au/statements/77/ | C20: =VLOOKUP($A20,Sheet1!$A$2:$I$6793,2,FALSE) -> Normal | D20: =VLOOKUP($A20,Sheet1!$A$2:$I$6793,3,FALSE) -> Australia | E20: Caroma, Methven, Dorf, Clark | F20: 350-400M | G20: GWA GROUP LIMITED (15 055 964 380) | H20: Construction, civil engineering and building products | J20: 6 | K20: 0 | L20: 375.5 | M20: =IF($K20 < 0.15, "Not Scanned",IF($K20 < 0.55, "Partially Scanned",IF($K20 >= 0.55, "Fully Scanned","Not Found"))) -> Not Scanned | N20: 6 | O20: 0 | P20: 375.5 | Q20: =IF($K20 < 0.15, "Not Scanned",IF($K20 < 0.55, "Partially Scanned",IF($K20 >= 0.55, "Fully Scanned","Not Found"))) -> Not Scanned
A21: 79 | B21: https://modernslaveryregister.gov.au/statements/79/ | C21: =VLOOKUP($A21,Sheet1!$A$2:$I$6793,2,FALSE) -> Normal | D21: =VLOOKUP($A21,Sheet1!$A$2:$I$6793,3,FALSE) -> Australia | E21: NEC | F21: 350-400M | G21: NEC AUSTRALIA PTY LTD (86 001 217 527) | J21: 3 | K21: 0.33333333 | L21: 361 | M21: =IF($K21 < 0.15, "Not Scanned",IF($K21 < 0.55, "Partially Scanned",IF($K21 >= 0.55, "Fully Scanned","Not Found"))) -> Partially Scanned | N21: 3 | O21: 0.33333333 | P21: 361 | Q21: =IF($K21 < 0.15, "Not Scanned",IF($K21 < 0.55, "Partially Scanned",IF($K21 >= 0.55, "Fully Scanned","Not Found"))) -> Partially Scanned
A22: 83 | B22: https://modernslaveryregister.gov.au/statements/83/ | C22: =VLOOKUP($A22,Sheet1!$A$2:$I$6793,2,FALSE) -> Normal | D22: =VLOOKUP($A22,Sheet1!$A$2:$I$6793,3,FALSE) -> Australia | E22: Dexus | F22: 1BN+ | G22: DEXUS FUNDS MANAGEMENT LIMITED (24 060 920 783) | J22: 5 | K22: 0 | L22: 471 | M22: =IF($K22 < 0.15, "Not Scanned",IF($K22 < 0.55, "Partially Scanned",IF($K22 >= 0.55, "Fully Scanned","Not Found"))) -> Not Scanned | N22: 5 | O22: 0 | P22: 471 | Q22: =IF($K22 < 0.15, "Not Scanned",IF($K22 < 0.55, "Partially Scanned",IF($K22 >= 0.55, "Fully Scanned","Not Found"))) -> Not Scanned
A23: 88 | B23: https://modernslaveryregister.gov.au/statements/88/ | C23: =VLOOKUP($A23,Sheet1!$A$2:$I$6793,2,FALSE) -> Normal | D23: =VLOOKUP($A23,Sheet1!$A$2:$I$6793,3,FALSE) -> Australia | F23: 1BN+ | G23: Origin Energy Limited | J23: 14 | K23: 0.071428571 | L23: 369 | M23: =IF($K23 < 0.15, "Not Scanned",IF($K23 < 0.55, "Partially Scanned",IF($K23 >= 0.55, "Fully Scanned","Not Found"))) -> Not Scanned | N23: 14 | O23: 0.071428571 | P23: 369 | Q23: =IF($K23 < 0.15, "Not Scanned",IF($K23 < 0.55, "Partially Scanned",IF($K23 >= 0.55, "Fully Scanned","Not Found"))) -> Not Scanned
A24: 91 | B24: https://modernslaveryregister.gov.au/statements/91/ | C24: =VLOOKUP($A24,Sheet1!$A$2:$I$6793,2,FALSE) -> Normal | D24: =VLOOKUP($A24,Sheet1!$A$2:$I$6793,3,FALSE) -> Australia | E24: M&C Saatchi Melbourne Pty Ltd, M&C Saatchi Sport and Entertainment Pty Ltd, Bohemia Group Pty Ltd, Re Team Australia Pty Ltd, Yes Agency Australia Pty Ltd, Greenhouse Australia Pty Ltd, This Film Studio Pty Ltd, The Source Australia Pty Ltd, Resolution Design Pty Ltd, Elastic Production Pty Ltd, Hidden Characters Pty Ltd, Tricky Jigsaw Pty Ltd, Ugly Sydney pty Ltd, Saatchi Ventures Pty Ltd, House Key Productions Pty Ltd | F24: Unknown | G24: M & C SAATCHI AGENCY PTY LIMITED (30 069 431 054) | J24: 2 | K24: 1 | L24: 0 | M24: =IF($K24 < 0.15, "Not Scanned",IF($K24 < 0.55, "Partially Scanned",IF($K24 >= 0.55, "Fully Scanned","Not Found"))) -> Fully Scanned | N24: 2 | O24: 1 | P24: 0 | Q24: =IF($K24 < 0.15, "Not Scanned",IF($K24 < 0.55, "Partially Scanned",IF($K24 >= 0.55, "Fully Scanned","Not Found"))) -> Fully Scanned
A25: 95 | B25: https://modernslaveryregister.gov.au/statements/95/ | C25: =VLOOKUP($A25,Sheet1!$A$2:$I$6793,2,FALSE) -> Joint | D25: =VLOOKUP($A25,Sheet1!$A$2:$I$6793,3,FALSE) -> Australia | E25: ASX, ASX24, Austraclear, ASX Clear, ASX Clear (Futures) | F25: 1BN+ | G25: ASX CLEAR (FUTURES) PTY LIMITED (91 050 615 864), ASX CLEARING CORPORATION PTY LIMITED (45 087 801 554), ASX LIMITED (98 008 624 691), ASX OPERATIONS PTY. LTD. (42 004 523 782) | J25: 10 | K25: 0.1 | L25: 317 | M25: =IF($K25 < 0.15, "Not Scanned",IF($K25 < 0.55, "Partially Scanned",IF($K25 >= 0.55, "Fully Scanned","Not Found"))) -> Not Scanned | N25: 10 | O25: 0.1 | P25: 317 | Q25: =IF($K25 < 0.15, "Not Scanned",IF($K25 < 0.55, "Partially Scanned",IF($K25 >= 0.55, "Fully Scanned","Not Found"))) -> Not Scanned
A26: 96 | B26: https://modernslaveryregister.gov.au/statements/96/ | C26: =VLOOKUP($A26,Sheet1!$A$2:$I$6793,2,FALSE) -> Joint | D26: =VLOOKUP($A26,Sheet1!$A$2:$I$6793,3,FALSE) -> United States of America | E26: Intel, McAfee | F26: 150-200M | G26: Intel Australia Pty, Limited, McAfee Australia Pty, Limited | J26: 8 | K26: 0.125 | L26: 559.5 | M26: =IF($K26 < 0.15, "Not Scanned",IF($K26 < 0.55, "Partially Scanned",IF($K26 >= 0.55, "Fully Scanned","Not Found"))) -> Not Scanned | N26: 8 | O26: 0.125 | P26: 559.5 | Q26: =IF($K26 < 0.15, "Not Scanned",IF($K26 < 0.55, "Partially Scanned",IF($K26 >= 0.55, "Fully Scanned","Not Found"))) -> Not Scanned
A27: 97 | B27: https://modernslaveryregister.gov.au/statements/97/ | C27: =VLOOKUP($A27,Sheet1!$A$2:$I$6793,2,FALSE) -> Joint | D27: =VLOOKUP($A27,Sheet1!$A$2:$I$6793,3,FALSE) -> Australia | E27: Nando's | F27: Unknown | G27: NANDO'S AUSTRALIA PTY LTD (20 079 066 407), NANDO'S PERI-PERI AUSTRALIA PTY LTD (86 627 885 956) | J27: 10 | K27: 0 | L27: 530 | M27: =IF($K27 < 0.15, "Not Scanned",IF($K27 < 0.55, "Partially Scanned",IF($K27 >= 0.55, "Fully Scanned","Not Found"))) -> Not Scanned | N27: 10 | O27: 0 | P27: 530 | Q27: =IF($K27 < 0.15, "Not Scanned",IF($K27 < 0.55, "Partially Scanned",IF($K27 >= 0.55, "Fully Scanned","Not Found"))) -> Not Scanned
A28: 103 | B28: https://modernslaveryregister.gov.au/statements/103/ | C28: =VLOOKUP($A28,Sheet1!$A$2:$I$6793,2,FALSE) -> Normal | D28: =VLOOKUP($A28,Sheet1!$A$2:$I$6793,3,FALSE) -> Australia | E28: Stockland | F28: 1BN+ | G28: STOCKLAND CORPORATION LTD (43 000 181 733) | J28: 8 | K28: 0 | L28: 432 | M28: =IF($K28 < 0.15, "Not Scanned",IF($K28 < 0.55, "Partially Scanned",IF($K28 >= 0.55, "Fully Scanned","Not Found"))) -> Not Scanned | N28: 8 | O28: 0 | P28: 432 | Q28: =IF($K28 < 0.15, "Not Scanned",IF($K28 < 0.55, "Partially Scanned",IF($K28 >= 0.55, "Fully Scanned","Not Found"))) -> Not Scanned
A29: 106 | B29: https://modernslaveryregister.gov.au/statements/106/ | C29: =VLOOKUP($A29,Sheet1!$A$2:$I$6793,2,FALSE) -> Normal | D29: =VLOOKUP($A29,Sheet1!$A$2:$I$6793,3,FALSE) -> Australia | E29: Allhomes, Australian Property Monitors, Commercial Real Estate, Domain, Domain Insure, Domain Loan Finder, Domain Review, Homepass, Pricefinder | F29: 250-300M | G29: DOMAIN HOLDINGS AUSTRALIA LIMITED (43 094 154 364) | J29: 4 | K29: 0.25 | L29: 442 | M29: =IF($K29 < 0.15, "Not Scanned",IF($K29 < 0.55, "Partially Scanned",IF($K29 >= 0.55, "Fully Scanned","Not Found"))) -> Partially Scanned | N29: 4 | O29: 0.25 | P29: 442 | Q29: =IF($K29 < 0.15, "Not Scanned",IF($K29 < 0.55, "Partially Scanned",IF($K29 >= 0.55, "Fully Scanned","Not Found"))) -> Partially Scanned
A30: 113 | B30: https://modernslaveryregister.gov.au/statements/113/ | C30: =VLOOKUP($A30,Sheet1!$A$2:$I$6793,2,FALSE) -> Normal | D30: =VLOOKUP($A30,Sheet1!$A$2:$I$6793,3,FALSE) -> Czech Republic, United Kingdom | E30: Avast plc, Avast Software s.r.o., AVG Technologies | F30: 800-900M | G30: AVG TECHNOLOGIES AU PTY LTD (79 159 743 978) | J30: 6 | K30: 0 | L30: 339.5 | M30: =IF($K30 < 0.15, "Not Scanned",IF($K30 < 0.55, "Partially Scanned",IF($K30 >= 0.55, "Fully Scanned","Not Found"))) -> Not Scanned | N30: 6 | O30: 0 | P30: 339.5 | Q30: =IF($K30 < 0.15, "Not Scanned",IF($K30 < 0.55, "Partially Scanned",IF($K30 >= 0.55, "Fully Scanned","Not Found"))) -> Not Scanned
A31: 115 | B31: https://modernslaveryregister.gov.au/statements/115/ | C31: =VLOOKUP($A31,Sheet1!$A$2:$I$6793,2,FALSE) -> Normal | D31: =VLOOKUP($A31,Sheet1!$A$2:$I$6793,3,FALSE) -> Australia | E31: Ethical Merch Co | F31: 0-99M | G31: CONCIERGE CONTACTS PTY. LTD. (53 149 081 756) | J31: 20 | K31: 0.2 | L31: 143.5 | M31: =IF($K31 < 0.15, "Not Scanned",IF($K31 < 0.55, "Partially Scanned",IF($K31 >= 0.55, "Fully Scanned","Not Found"))) -> Partially Scanned | N31: 20 | O31: 0.2 | P31: 143.5 | Q31: =IF($K31 < 0.15, "Not Scanned",IF($K31 < 0.55, "Partially Scanned",IF($K31 >= 0.55, "Fully Scanned","Not Found"))) -> Partially Scanned
A32: 120 | B32: https://modernslaveryregister.gov.au/statements/120/ | C32: =VLOOKUP($A32,Sheet1!$A$2:$I$6793,2,FALSE) -> Joint | D32: =VLOOKUP($A32,Sheet1!$A$2:$I$6793,3,FALSE) -> Australia | E32: Betta Home Living, Designer Appliances, Furniture Zone, Norj, Betta, Torino | F32: 100-150M | G32: BSR Australia Limited (84 122 529 695), BSR Franchising Pty Ltd (21 122 556 094) | J32: 2 | K32: 0 | L32: 434 | M32: =IF($K32 < 0.15, "Not Scanned",IF($K32 < 0.55, "Partially Scanned",IF($K32 >= 0.55, "Fully Scanned","Not Found"))) -> Not Scanned | N32: 2 | O32: 0 | P32: 434 | Q32: =IF($K32 < 0.15, "Not Scanned",IF($K32 < 0.55, "Partially Scanned",IF($K32 >= 0.55, "Fully Scanned","Not Found"))) -> Not Scanned
A33: 123 | B33: https://modernslaveryregister.gov.au/statements/123/ | C33: =VLOOKUP($A33,Sheet1!$A$2:$I$6793,2,FALSE) -> Normal | D33: =VLOOKUP($A33,Sheet1!$A$2:$I$6793,3,FALSE) -> Japan | F33: Unknown | G33: MITSUBISHI AUSTRALIA LIMITED (81 004 354 278) | J33: 3 | K33: 0 | L33: 343 | M33: =IF($K33 < 0.15, "Not Scanned",IF($K33 < 0.55, "Partially Scanned",IF($K33 >= 0.55, "Fully Scanned","Not Found"))) -> Not Scanned | N33: 3 | O33: 0 | P33: 343 | Q33: =IF($K33 < 0.15, "Not Scanned",IF($K33 < 0.55, "Partially Scanned",IF($K33 >= 0.55, "Fully Scanned","Not Found"))) -> Not Scanned
A34: 126 | B34: https://modernslaveryregister.gov.au/statements/126/ | C34: =VLOOKUP($A34,Sheet1!$A$2:$I$6793,2,FALSE) -> Joint | D34: =VLOOKUP($A34,Sheet1!$A$2:$I$6793,3,FALSE) -> Australia | E34: Saracen | F34: 1BN+ | G34: BLIGH RESOURCES LIMITED (83 130 964 162), KALGOORLIE CONSOLIDATED GOLD MINES PTY LTD (97 009 377 619), SARACEN GOLDFIELDS PTY LTD (44 637 156 579), SARACEN GOLD MINES PTY LIMITED (14 116 649 122), SARACEN KALGOORLIE PTY LIMITED (19 008 143 137), SARACEN METALS PTY LIMITED (15 107 154 727), SARACEN MINERAL HOLDINGS LIMITED (52 009 215 347), SARACEN NICKEL PTY LTD (57 635 649 606), S R Mining Pty Ltd (91 151 605 417), TALISMAN NICKEL PTY LTD (42 601 140 185) | J34: 5 | K34: 0.2 | L34: 386 | M34: =IF($K34 < 0.15, "Not Scanned",IF($K34 < 0.55, "Partially Scanned",IF($K34 >= 0.55, "Fully Scanned","Not Found"))) -> Partially Scanned | N34: 5 | O34: 0.2 | P34: 386 | Q34: =IF($K34 < 0.15, "Not Scanned",IF($K34 < 0.55, "Partially Scanned",IF($K34 >= 0.55, "Fully Scanned","Not Found"))) -> Partially Scanned
A35: 132 | B35: https://modernslaveryregister.gov.au/statements/132/ | C35: =VLOOKUP($A35,Sheet1!$A$2:$I$6793,2,FALSE) -> Normal | D35: =VLOOKUP($A35,Sheet1!$A$2:$I$6793,3,FALSE) -> Australia | E35: Knights Rugby League, The Executive Inn, The Wests Group Australia, Wests | F35: 150-200M | G35: WESTERN SUBURBS (N'CLE) LEAGUES CLUB LTD (24 000 973 919) | J35: 4 | K35: 1 | L35: 0 | M35: =IF($K35 < 0.15, "Not Scanned",IF($K35 < 0.55, "Partially Scanned",IF($K35 >= 0.55, "Fully Scanned","Not Found"))) -> Fully Scanned | N35: 4 | O35: 1 | P35: 0 | Q35: =IF($K35 < 0.15, "Not Scanned",IF($K35 < 0.55, "Partially Scanned",IF($K35 >= 0.55, "Fully Scanned","Not Found"))) -> Fully Scanned
A36: 134 | B36: https://modernslaveryregister.gov.au/statements/134/ | C36: =VLOOKUP($A36,Sheet1!$A$2:$I$6793,2,FALSE) -> Joint | D36: =VLOOKUP($A36,Sheet1!$A$2:$I$6793,3,FALSE) -> Australia | E36: SOUTH32 | F36: 1BN+ | G36: DENDROBIUM COAL PTY LTD (85 098 744 088), ENDEAVOUR COAL PTY LIMITED (38 099 830 476), GROOTE EYLANDT MINING COMPANY PROPRIETARY LIMITED (26 004 618 491), ILLAWARRA COAL HOLDINGS PTY LTD (69 093 857 286), SOUTH32 ALUMINIUM (RAA) PTY LTD (54 095 831 119), SOUTH32 ALUMINIUM (WORSLEY) PTY LTD (33 088 336 921), SOUTH32 CANNINGTON PROPRIETARY LIMITED (48 125 530 967), SOUTH32 LIMITED (84 093 732 597), TASMANIAN ELECTRO METALLURGICAL COMPANY PROPRIETARY LIMITED (23 004 456 035) | J36: 20 | K36: 0.1 | L36: 389.5 | M36: =IF($K36 < 0.15, "Not Scanned",IF($K36 < 0.55, "Partially Scanned",IF($K36 >= 0.55, "Fully Scanned","Not Found"))) -> Not Scanned | N36: 20 | O36: 0.1 | P36: 389.5 | Q36: =IF($K36 < 0.15, "Not Scanned",IF($K36 < 0.55, "Partially Scanned",IF($K36 >= 0.55, "Fully Scanned","Not Found"))) -> Not Scanned
A37: 136 | B37: https://modernslaveryregister.gov.au/statements/136/ | C37: =VLOOKUP($A37,Sheet1!$A$2:$I$6793,2,FALSE) -> Joint | D37: =VLOOKUP($A37,Sheet1!$A$2:$I$6793,3,FALSE) -> Australia | E37: Autosports Group Limited | F37: 1BN+ | G37: A.C.N. 633 925 050 PTY LTD (59 633 925 050), ASG BRISBANE PTY LTD (72 614 297 684), ASG MELBOURNE PTY LTD (64 616 840 110), AUTOSPORTS BRISBANE PTY LTD (13 603 332 752), AUTOSPORTS CASTLE HILL PTY LTD (65 163 974 481), AUTOSPORTS FIVE DOCK PTY LIMITED (95 118 786 762), AUTOSPORTS GROUP LIMITED (54 614 505 261), AUTOSPORTS LEICHHARDT PTY LTD (38 161 160 765), AUTOSPORTS PRESTIGE PTY LIMITED (42 096 909 698), Autosports Sutherland Pty Limited (60 125 720 998), Betar Prestige Cars Pty Ltd (60 118 667 913), BIRCHGROVE FINANCE PTY LIMITED (90 165 682 057), Modena Trading Pty Ltd (27 140 018 015), Mosman Prestige Cars Pty Ltd (16 149 346 476), NEW CENTENARY MAZDA PTY LTD (21 168 183 800), NEW CENTENARY PTY LIMITED (21 168 183 864), PRESTIGE AUTO TRADERS AUSTRALIA PTY LIMITED (11 105 105 771), PRESTIGE GROUP HOLDINGS PTY LTD (71 073 650 512), PRESTIGE REPAIR WORKS PTY LTD (44 611 760 126) | J37: 5 | K37: 0.2 | L37: 186 | M37: =IF($K37 < 0.15, "Not Scanned",IF($K37 < 0.55, "Partially Scanned",IF($K37 >= 0.55, "Fully Scanned","Not Found"))) -> Partially Scanned | N37: 5 | O37: 0.2 | P37: 186 | Q37: =IF($K37 < 0.15, "Not Scanned",IF($K37 < 0.55, "Partially Scanned",IF($K37 >= 0.55, "Fully Scanned","Not Found"))) -> Partially Scanned
A38: 139 | B38: https://modernslaveryregister.gov.au/statements/139/ | C38: =VLOOKUP($A38,Sheet1!$A$2:$I$6793,2,FALSE) -> Normal | D38: =VLOOKUP($A38,Sheet1!$A$2:$I$6793,3,FALSE) -> Australia | E38: QV, Aqium, SUNSENSE, MOOV, DermAid, Egoderm, Egozite, Elucent, Pinetarsol, Resolve, Sebitar, SolvEasy, SOOV | F38: 150-200M | G38: EGO PHARMACEUTICALS PTY LTD (86 005 142 361) | J38: 7 | K38: 0.14285714 | L38: 343 | M38: =IF($K38 < 0.15, "Not Scanned",IF($K38 < 0.55, "Partially Scanned",IF($K38 >= 0.55, "Fully Scanned","Not Found"))) -> Not Scanned | N38: 7 | O38: 0.14285714 | P38: 343 | Q38: =IF($K38 < 0.15, "Not Scanned",IF($K38 < 0.55, "Partially Scanned",IF($K38 >= 0.55, "Fully Scanned","Not Found"))) -> Not Scanned
A39: 142 | B39: https://modernslaveryregister.gov.au/statements/142/ | C39: =VLOOKUP($A39,Sheet1!$A$2:$I$6793,2,FALSE) -> Normal | D39: =VLOOKUP($A39,Sheet1!$A$2:$I$6793,3,FALSE) -> Australia | E39: GHD | F39: 1BN+ | G39: GHD PTY LTD (39 008 488 373) | J39: 6 | K39: 0 | L39: 326 | M39: =IF($K39 < 0.15, "Not Scanned",IF($K39 < 0.55, "Partially Scanned",IF($K39 >= 0.55, "Fully Scanned","Not Found"))) -> Not Scanned | N39: 6 | O39: 0 | P39: 326 | Q39: =IF($K39 < 0.15, "Not Scanned",IF($K39 < 0.55, "Partially Scanned",IF($K39 >= 0.55, "Fully Scanned","Not Found"))) -> Not Scanned
A40: 144 | B40: https://modernslaveryregister.gov.au/statements/144/ | C40: =VLOOKUP($A40,Sheet1!$A$2:$I$6793,2,FALSE) -> Joint | D40: =VLOOKUP($A40,Sheet1!$A$2:$I$6793,3,FALSE) -> Australia | E40: Channel Nine, Sydney Morning Herald, Stan, The Age, The Australian Financial Review, 9Now | F40: 1BN+ | G40: NINE ENTERTAINMENT CO. HOLDINGS LIMITED (60 122 203 892) | J40: 3 | K40: 0 | L40: 534 | M40: =IF($K40 < 0.15, "Not Scanned",IF($K40 < 0.55, "Partially Scanned",IF($K40 >= 0.55, "Fully Scanned","Not Found"))) -> Not Scanned | N40: 3 | O40: 0 | P40: 534 | Q40: =IF($K40 < 0.15, "Not Scanned",IF($K40 < 0.55, "Partially Scanned",IF($K40 >= 0.55, "Fully Scanned","Not Found"))) -> Not Scanned
...

Sheet Sheet1
A1: StatementId | B1: Type | C1: Countries | D1: Trademarks | E1: AnnualRevenue | F1: Entities | G1: Link | H1: IndustrySectors | I1: OverseasObligations
A2: 12365 | B2: Joint | C2: Germany | D2: HELLA | E2: 600-700M | F2: HELLA ASIA PACIFIC HOLDINGS PTY LTD (59 007 958 787), HELLA ASIA PACIFIC PTY LTD (46 004 516 947), HELLA AUSTRALIA PTY LTD (77 006 256 524) | G2: https://modernslaveryregister.gov.au/statements/12365/ | H2: Automotive, machinery and heavy electrical equipment | I2: United Kingdom Modern Slavery Act 2015
A3: 12355 | B3: Normal | C3: Australia | D3: Comcare | E3: 300-350M | F3: COMCARE AUSTRALIA (41 640 788 304) | G3: https://modernslaveryregister.gov.au/statements/12355/ | H3: Government Sector
A4: 12306 | B4: Joint | C4: Australia | D4: BOQ, VMA, ME, BOQ Business, BOQ Finance, BOQ Specialist | E4: 1BN+ | F4: BANK OF QUEENSLAND LIMITED (32 009 656 740), MEMBERS EQUITY BANK LIMITED (56 070 887 679) | G4: https://modernslaveryregister.gov.au/statements/12306/ | H4: Financial, insurance and real estate activities
A5: 12308 | B5: Joint | C5: Australia | E5: 450-500M | F5: HWLE CONSULTING PTY LTD (47 158 617 497), THE MARTINEZ HWL PRACTICE TRUST & THE EAST HWL PRACTICE TRUST & THE WARAT HWL PRACTICE TRUST & THE MARIN HWL PRACTICE TRUST & OTHERS (37 246 549 189) | G5: https://modernslaveryregister.gov.au/statements/12308/ | H5: Professional and administrative services and supplies, including legal, consulting and accounting services
A6: 12307 | B6: Normal | C6: Australia | E6: 100-150M | F6: CENTRAL GIPPSLAND HEALTH SERVICE (85 050 485 681) | G6: https://modernslaveryregister.gov.au/statements/12307/ | H6: Healthcare and pharmaceuticals
A7: 12294 | B7: Normal | C7: Australia | D7: AUSTRALIAN NO.1, GMP PHARMACEUTICALS PTY LIMITED | E7: 200-250M | F7: GMP PHARMACEUTICALS PTY LIMITED (80 063 353 006) | G7: https://modernslaveryregister.gov.au/statements/12294/ | H7: Healthcare and pharmaceuticals
A8: 9924 | B8: Joint | C8: Japan | D8: Miki House | E8: 150-200M | F8: MIKI SHOKO CO., LTD. | G8: https://modernslaveryregister.gov.au/statements/9924/ | H8: Fashion, textiles, apparel and luxury goods | I8: United Kingdom Modern Slavery Act 2015
A9: 11658 | B9: Joint | C9: Australia | E9: 1BN+ | F9: RESMED ASIA PACIFIC LIMITED (86 070 076 470), RESMED HOLDINGS PTY LTD (28 003 765 133), RESMED PTY LTD (30 003 765 142) | G9: https://modernslaveryregister.gov.au/statements/11658/ | H9: Durable consumer goods, including electronics and appliances, home furnishings and other accessories Information technology and telecommunication Healthcare and pharmaceuticals | I9: United Kingdom Modern Slavery Act 2015 California Transparency in Supply Chains Act 2010
A10: 11195 | B10: Normal | C10: Australia | D10: Karoon Energy Ltd | E10: 350-400M | F10: Karoon Energy Ltd (53 107 001 338) | G10: https://modernslaveryregister.gov.au/statements/11195/ | H10: Mining, metals, chemicals and resources (including oil and gas)
A11: 10580 | B11: Joint | C11: Australia | D11: Civil Contractors (Aust) Pty Ltd, Winslow Constructors Pty Ltd, Winslow Infrastructure Pty Ltd | E11: 900M-1BN | F11: WINSLOW CONSTRUCTORS PTY LTD (73 006 581 764), WINSLOW INFRASTRUCTURE PTY. LTD. (72 119 092 385) | G11: https://modernslaveryregister.gov.au/statements/10580/ | H11: Construction, civil engineering and building products
A12: 10683 | B12: Normal | C12: Japan | E12: 100-150M | F12: MUFG BANK, LTD. (75 103 418 882) | G12: https://modernslaveryregister.gov.au/statements/10683/ | H12: Financial, insurance and real estate activities | I12: United Kingdom Modern Slavery Act 2015
A13: 11151 | B13: Joint | C13: Australia | E13: 400-450M | F13: SCOTT'S REFRIGERATED FREIGHTWAYS PTY LTD (41 162 034 326), SCOTTSRL PTY LTD (64 112 854 912) | G13: https://modernslaveryregister.gov.au/statements/11151/ | H13: Transportation, logistics, and storage
A14: 12088 | B14: Joint | C14: Australia, United Kingdom, United States of America | D14: Pendal Group Limited, Pendal Fund Services Limited, Pendal Institutional Limited, JO Hambro Capital Management Limited, Regnan – Governance Research and Engagement Pty Ltd, Pendal UK Limited, Pendal USA Inc., Thompson Siegel & Walmsley LLC | E14: 1BN+ | F14: PENDAL FUND SERVICES LIMITED (13 161 249 332), PENDAL GROUP LIMITED (28 126 385 822), PENDAL INSTITUTIONAL LIMITED (17 126 390 627), Pendal UK Limited, Pendal USA Inc., Regnan - Governance Research and Engagement Pty Limited (93 125 320 041) | G14: https://modernslaveryregister.gov.au/statements/12088/ | H14: Financial, insurance and real estate activities | I14: United Kingdom Modern Slavery Act 2015
A15: 12086 | B15: Normal | C15: Australia | E15: 150-200M | F15: TOMRA CLEANAWAY PTY LIMITED (43 620 427 116) | G15: https://modernslaveryregister.gov.au/statements/12086/ | H15: Waste management and recycling
A16: 12085 | B16: Joint | C16: Australia | E16: 800-900M | F16: NICK SCALI LIMITED (82 000 403 896), PLUSH-THINK SOFAS PTY LTD (55 080 012 595) | G16: https://modernslaveryregister.gov.au/statements/12085/ | H16: Durable consumer goods, including electronics and appliances, home furnishings and other accessories
A17: 12084 | B17: Normal | C17: Australia | D17: Probiotec Limited, Probiotec Pharma, LJM Marketing Services, Multipack-LJM, South Pack Laboratories, ABS, HH Packaging | E17: 100-150M | F17: PROBIOTEC LIMITED (91 075 170 151) | G17: https://modernslaveryregister.gov.au/statements/12084/ | H17: Healthcare and pharmaceuticals
A18: 12081 | B18: Normal | C18: Australia | E18: 100-150M | F18: WELLWAYS AUSTRALIA LIMITED (93 093 357 165) | G18: https://modernslaveryregister.gov.au/statements/12081/ | H18: Charitable / not-for-profit activities
A19: 12076 | B19: Joint | C19: Australia | E19: 300-350M | F19: ROYAN GROUP BIDCO PTY LIMITED (56 638 670 470), ROYAN GROUP HOLDCO PTY LIMITED (91 638 670 238), ROYAN GROUP MIDCO PTY LIMITED (25 638 670 336) | G19: https://modernslaveryregister.gov.au/statements/12076/ | H19: Transportation, logistics, and storage
A20: 12075 | B20: Joint | C20: Australia | D20: FCM, Corporate Traveller, FLight Centre | E20: 1BN+ | F20: AUSTRALIAN OPCO PTY LTD (20 003 279 534), FLIGHT CENTRE TRAVEL GROUP LIMITED (25 003 377 188) | G20: https://modernslaveryregister.gov.au/statements/12075/ | H20: Consumer services, including accommodation, hospitality, tourism and leisure Education and research | I20: United Kingdom Modern Slavery Act 2015
A21: 12074 | B21: Normal | C21: Australia | D21: Fur Life Vet; Country Vet | E21: 150-200M | F21: APIAM ANIMAL HEALTH LIMITED (50 604 961 024) | G21: https://modernslaveryregister.gov.au/statements/12074/ | H21: Food and beverages, agriculture and fishing
A22: 12073 | B22: Normal | C22: Australia | E22: 1BN+ | F22: METRO TRAINS AUSTRALIA PTY LTD (88 614 061 960) | G22: https://modernslaveryregister.gov.au/statements/12073/ | H22: Transportation, logistics, and storage
A23: 12072 | B23: Joint | C23: Australia | D23: Fidelity | E23: 200-250M | F23: FIL INVESTMENT MANAGEMENT (AUSTRALIA) LIMITED (34 006 773 575), FIL Responsible Entity (Australia) Limited (33 148 059 009), The Trustee for Fidelity Wholesale Plus Australian Equities Fund (26 876 355 623) | G23: https://modernslaveryregister.gov.au/statements/12072/ | H23: Financial, insurance and real estate activities
A24: 12070 | B24: Joint | C24: Australia | D24: Credit Corp Group Limited, Credit Corp Financial Services Pty Limited, Collection House Limited, Credit Corp Services Pty Limited | E24: 800-900M | F24: COLLECTION HOUSE LIMITED (74 010 230 716), Credit Corp Financial Services Pty Limited (39 146 525 706), CREDIT CORP GROUP LIMITED (33 092 697 151), CREDIT CORP SERVICES PTY LIMITED (95 082 928 872) | G24: https://modernslaveryregister.gov.au/statements/12070/ | H24: Financial, insurance and real estate activities
A25: 11903 | B25: Joint | C25: Australia | D25: Ray White, Loan Market Group | E25: 1BN+ | F25: GROUP ADMINISTRATION AUSTRALIA PTY LTD (30 010 374 731), LOAN MARKET GROUP PTY LTD (83 105 221 967), MINGLECLIFF (QLD) PTY LTD & TUPMAN PTY. LTD. (21 464 496 649) | G25: https://modernslaveryregister.gov.au/statements/11903/ | H25: Financial, insurance and real estate activities
A26: 12069 | B26: Normal | C26: Australia | E26: 100-150M | F26: GENPACT AUSTRALIA PTY LTD (15 616 571 423) | G26: https://modernslaveryregister.gov.au/statements/12069/ | H26: Information technology and telecommunication Professional and administrative services and supplies, including legal, consulting and accounting services | I26: United Kingdom Modern Slavery Act 2015
A27: 12068 | B27: Normal | C27: Australia | D27: Linfox, Armaguard, Linfox Logistics | E27: Unknown | F27: LINFOX PROPRIETARY LIMITED (59 004 667 298) | G27: https://modernslaveryregister.gov.au/statements/12068/ | H27: Transportation, logistics, and storage
A28: 12067 | B28: Normal | C28: Australia | E28: 100-150M | F28: Magi Enterprises Pty Ltd (49 154 423 613) | G28: https://modernslaveryregister.gov.au/statements/12067/ | H28: Fashion, textiles, apparel and luxury goods
A29: 12066 | B29: Joint | C29: Australia, Singapore | D29: Civmec Construction & Engineering Pty Ltd, Civmec Construction & Engineering Singapore Pte Ltd, Civmec-MALA PNG Ltd, Civmec Holdings Pty Ltd, Multidiscipline Solutions Pty Ltd, Civmec Pipe Products Pty Ltd, Civmec Electrical & Instrumentation Pty Ltd, Civmec-DLG Pty Ltd, Forgacs Marine & Defence Pty Ltd Civmec, Civmec Construction & Engineering Africa Ltd, ForgacsValco Pty Ltd, Construction & Engineering Uganda Ltd | E29: 800-900M | F29: CIVMEC LIMITED (50 604 316 690) | G29: https://modernslaveryregister.gov.au/statements/12066/ | H29: Mining, metals, chemicals and resources (including oil and gas) Construction, civil engineering and building products Defence and aerospace
A30: 11869 | B30: Normal | C30: Australia | D30: Camilla Australia Pty Ltd | E30: 100-150M | F30: CAMILLA AUSTRALIA PTY LTD (67 135 300 382) | G30: https://modernslaveryregister.gov.au/statements/11869/ | H30: Fashion, textiles, apparel and luxury goods
A31: 12065 | B31: Normal | C31: Australia | E31: 100-150M | F31: PLE COMPUTERS PTY LTD (48 051 046 596) | G31: https://modernslaveryregister.gov.au/statements/12065/ | H31: Durable consumer goods, including electronics and appliances, home furnishings and other accessories
A32: 12064 | B32: Joint | C32: Australia | D32: Cromwell, Property Group, cromwell property group | E32: 1BN+ | F32: CROMWELL CORPORATION LIMITED (44 001 056 980), CROMWELL PROPERTY SECURITIES LIMITED (11 079 147 809) | G32: https://modernslaveryregister.gov.au/statements/12064/ | H32: Financial, insurance and real estate activities | I32: United Kingdom Modern Slavery Act 2015
A33: 12063 | B33: Normal | C33: Australia | E33: 100-150M | F33: Enviro Pipes Pty Ltd (84 130 666 518) | G33: https://modernslaveryregister.gov.au/statements/12063/ | H33: Other
A34: 12062 | B34: Normal | C34: Australia | D34: The Smith Family, VIEW Clubs of Australia | E34: 100-150M | F34: THE SMITH FAMILY (28 000 030 179) | G34: https://modernslaveryregister.gov.au/statements/12062/ | H34: Charitable / not-for-profit activities
A35: 11890 | B35: Joint | C35: Switzerland | E35: 1BN+ | F35: AMCOR FLEXIBLES (AUSTRALIA) PTY LTD (46 113 833 748), AMCOR FLEXIBLES GROUP PTY LTD (33 113 833 695), Amcor plc, AMCOR PTY LTD (62 000 017 372) | G35: https://modernslaveryregister.gov.au/statements/11890/ | H35: Forestry, timber products, paper and containers and packaging | I35: United Kingdom Modern Slavery Act 2015 California Transparency in Supply Chains Act 2010
A36: 12061 | B36: Joint | C36: Australia | D36: Ambrose Building, Ambrose Construct Group, Construct Services, Inserve, Inserve Australia | E36: 200-250M | F36: AMBROSE CONSTRUCT GROUP PTY LTD (35 131 176 102), Inserve Australia Ltd (76 147 747 859) | G36: https://modernslaveryregister.gov.au/statements/12061/ | H36: Construction, civil engineering and building products
A37: 12060 | B37: Normal | C37: Australia | D37: Domino's Pizza | E37: 1BN+ | F37: DOMINO'S PIZZA ENTERPRISES LIMITED (16 010 489 326) | G37: https://modernslaveryregister.gov.au/statements/12060/ | H37: Food and beverages, agriculture and fishing
A38: 12057 | B38: Normal | C38: Australia | D38: Boom Logistics, Boom | E38: 200-250M | F38: BOOM LOGISTICS LTD (28 095 466 961) | G38: https://modernslaveryregister.gov.au/statements/12057/ | H38: Mining, metals, chemicals and resources (including oil and gas) Automotive, machinery and heavy electrical equipment Construction, civil engineering and building products Transportation, logistics, and storage Other
A39: 12029 | B39: Normal | C39: Australia | E39: 100-150M | F39: SOUTHERN PORTS AUTHORITY (30 044 341 250) | G39: https://modernslaveryregister.gov.au/statements/12029/ | H39: Transportation, logistics, and storage
A40: 12056 | B40: Normal | C40: Australia | E40: 100-150M | F40: AUSTRALIAN STEEL TRADERS PTY LTD (93 644 181 028) | G40: https://modernslaveryregister.gov.au/statements/12056/ | H40: Mining, metals, chemicals and resources (including oil and gas)
...
